<robot name="jumpbot" xmlns:xacro="http://ros.org/wiki/xacro">

<joint
    name="L_baselink_joint"
    type="revolute">
    <origin
      xyz="0.1065 0.0450000000000004 -0.0330000000000008"
      rpy="1.5707963267949 0 -1.5707963267949" />
    <parent
      link="base_link" />
    <child
      link="L_baselink" />
    <axis
      xyz="0 0 1" />
    <limit
      lower="-1.5707"
      upper="1.5707"
      effort="100"
      velocity="1" />
  </joint>
  <joint
    name="L_cam_joint"
    type="continuous">
    <origin
      xyz="-0.0620000000018907 -0.0915314647309971 -0.00417000000000045"
      rpy="1.57079632679489 -1.45724685889206 -1.57079632679489" />
    <parent
      link="L_baselink" />
    <child
      link="L_cam" />
    <axis
      xyz="0 0 1" />
  </joint>
  <joint
    name="L_leg3_joint"
    type="revolute">
    <origin
      xyz="-0.0660000000018272 -0.0883531819184021 0.0824162107442846"
      rpy="1.57079632681981 -0.853930194145867 -1.57079632681554" />
    <parent
      link="L_baselink" />
    <child
      link="L_leg3" />
    <axis
      xyz="0 0 -1" />
    <limit
      lower="0"
      upper="0"
      effort="0"
      velocity="0" />
  </joint>
  <joint
    name="L_leg1_L_joint"
    type="revolute">
    <origin
      xyz="0.150000000000081 0 -0.040000000000003"
      rpy="0 0 -1.74964597766658" />
    <parent
      link="L_leg3" />
    <child
      link="L_leg1_L" />
    <axis
      xyz="0 0 -1" />
    <limit
      lower="0"
      upper="0"
      effort="0"
      velocity="0" />
  </joint>
  <joint
    name="L_leg2_joint"
    type="revolute">
    <origin
      xyz="-0.0660000000025969 -0.1254831819183 0.0453000000002221"
      rpy="1.57079632679489 -1.00689911983256 -1.57079632681554" />
    <parent
      link="L_baselink" />
    <child
      link="L_leg2" />
    <axis
      xyz="0 0 1" />
    <limit
      lower="0"
      upper="0"
      effort="0"
      velocity="0" />
  </joint>
  <joint
    name="L_leg1_R_joint"
    type="revolute">
    <origin
      xyz="0.15000000000002 0 0.0199999999999946"
      rpy="0 0 0.450347739059501" />
    <parent
      link="L_leg2" />
    <child
      link="L_leg1_R" />
    <axis
      xyz="0 0 1" />
    <limit
      lower="0"
      upper="0"
      effort="0"
      velocity="0" />
  </joint>
  <joint
    name="L_motor_joint"
    type="fixed">
    <origin
      xyz="-0.105722674632221 -0.106408251881274 0.0420000000019356"
      rpy="0 0 0" />
    <parent
      link="L_leg1_R" />
    <child
      link="L_motor" />
    <axis
      xyz="0 0 0" />
  </joint>
  <joint
    name="L_wheel_joint"
    type="continuous">
    <origin
      xyz="0 0 0"
      rpy="0 0 0" />
    <parent
      link="L_motor" />
    <child
      link="L_wheel" />
    <axis
      xyz="0 0 -1" />
  </joint>
  <joint
    name="L_arm1_joint"
    type="revolute">
    <origin
      xyz="-0.1025 -0.0175 0.023998"
      rpy="1.5708 -1.4572 -1.5708" />
    <parent
      link="L_baselink" />
    <child
      link="L_arm1" />
    <axis
      xyz="0 0 -1" />
    <limit effort="1" velocity="1" lower="-1.5707" upper="1.5707"/>
  </joint>
  <joint
    name="L_arm2_joint"
    type="revolute">
    <origin
      xyz="-0.03552 -0.0040507 0.05"
      rpy="0.11355 -1.5708 0" />
    <parent
      link="L_arm1" />
    <child
      link="L_arm2" />
    <axis
      xyz="0 0 -1" />
    <limit effort="1" velocity="1" lower="-1.5707" upper="1.5707"/>
  </joint>
  <joint
    name="L_arm3_joint"
    type="revolute">
    <origin
      xyz="0.0899999999999991 0 -0.0630000000000002"
      rpy="3.14159265358979 0 -3.14159265358979" />
    <parent
      link="L_arm2" />
    <child
      link="L_arm3" />
    <axis
      xyz="0 0 -1" />
    <limit effort="1" velocity="1" lower="-1.5707" upper="1.5707"/>
  </joint>
  <joint
    name="R_baselink_joint"
    type="revolute">
    <origin
      xyz="0.1065 -0.045 -0.0330000000000002"
      rpy="1.5707963267949 0 -1.5707963267949" />
    <parent
      link="base_link" />
    <child
      link="R_baselink" />
    <axis
      xyz="0 0 1" />
    <limit
      lower="-1.5707"
      upper="1.5707"
      effort="100"
      velocity="1" />
  </joint>
  <joint
    name="R_cam_joint"
    type="continuous">
    <origin
      xyz="0.0489999999981055 -0.091531464733288 -0.00416999999999973"
      rpy="1.57079632679488 -1.45724685889206 -1.57079632679488" />
    <parent
      link="R_baselink" />
    <child
      link="R_cam" />
    <axis
      xyz="0 0 1" />
  </joint>
  <joint
    name="R_leg3_joint"
    type="revolute">
    <origin
      xyz="0.065999999998173 -0.0883531819214337 0.0824162107440945"
      rpy="1.5707963267949 -0.853721604418042 -1.57079632681554" />
    <parent
      link="R_baselink" />
    <child
      link="R_leg3" />
    <axis
      xyz="0 0 -1" />
    <limit
      lower="0"
      upper="0"
      effort="0"
      velocity="0" />
  </joint>
  <joint
    name="R_leg1_R_joint"
    type="revolute">
    <origin
      xyz="0.150000004607446 0 0.039999999999998"
      rpy="0 0 -1.74926931149431" />
    <parent
      link="R_leg3" />
    <child
      link="R_leg1_R" />
    <axis
      xyz="0 0 -1" />
    <limit
      lower="0"
      upper="0"
      effort="0"
      velocity="0" />
  </joint>
  <joint
    name="R_leg2_joint"
    type="revolute">
    <origin
      xyz="0.0659999999974047 -0.125483181921434 0.0453000000000003"
      rpy="1.57079632679489 -1.00668202156475 -1.57079632681554" />
    <parent
      link="R_baselink" />
    <child
      link="R_leg2" />
    <axis
      xyz="0 0 1" />
    <limit
      lower="0"
      upper="0"
      effort="0"
      velocity="0" />
  </joint>
  <joint
    name="R_leg1_L_joint"
    type="revolute">
    <origin
      xyz="0.149999999999984 0 0.0399999999999999"
      rpy="0 0 0.450564837327306" />
    <parent
      link="R_leg2" />
    <child
      link="R_leg1_L" />
    <axis
      xyz="0 0 1" />
    <limit
      lower="0"
      upper="0"
      effort="0"
      velocity="0" />
  </joint>
  <joint
    name="R_motor_joint"
    type="fixed">
    <origin
      xyz="-0.1057 -0.10643 -0.102"
      rpy="0 0 0" />
    <parent
      link="R_leg1_L" />
    <child
      link="R_motor" />
    <axis
      xyz="0 0 0" />
  </joint>
  <joint
    name="R_wheel_joint"
    type="continuous">
    <origin
      xyz="0 0 0"
      rpy="0 0 0" />
    <parent
      link="R_motor" />
    <child
      link="R_wheel" />
    <axis
      xyz="0 0 1" />
  </joint>
  <joint
    name="R_arm1_joint"
    type="revolute">
    <origin
      xyz="0.1025 -0.0175 0.023998"
      rpy="1.5708 -1.4572 -1.5708" />
    <parent
      link="R_baselink" />
    <child
      link="R_arm1" />
    <axis
      xyz="0 0 1" />
    <limit effort="1" velocity="1" lower="-1.5707" upper="1.5707"/>
  </joint>

  <joint
    name="R_arm2_joint"
    type="revolute">
    <origin
      xyz="0.03552 0.0040507 -0.05"
      rpy="-0.11355 1.5708 0" />
    <parent
      link="R_arm1" />
    <child
      link="R_arm2" />
    <axis
      xyz="0 0 -1" />
    <limit effort="1" velocity="1" lower="-1.5707" upper="1.5707"/>
  </joint>

  <joint
    name="R_arm3_joint"
    type="revolute">
    <origin
      xyz="0.09 0 -0.063"
      rpy="-3.1416 0 -3.1416" />
    <parent
      link="R_arm2" />
    <child
      link="R_arm3" />
    <axis
      xyz="0 0 -1" />
    <limit effort="1" velocity="1" lower="-1.5707" upper="1.5707"/>
  </joint>
</robot>